#VRML_SIM R2021a utf8
WorldInfo {
  coordinateSystem "NUE"
}
Viewpoint {
  orientation 1 0 0 4.71238898038469
  position 0.0017889063370893881 2.9199230077853064 -0.0393559394159658
}
TexturedBackground {
}
TexturedBackgroundLight {
}
RectangleArena {
  floorSize 1.5 1.5
  floorAppearance PBRAppearance {
    roughness 1
    roughnessMap ImageTexture {
      url [
        "textures/parquetry/chequered_parquetry_roughness.jpg"
      ]
    }
    metalness 0
    normalMap ImageTexture {
      url [
        "textures/parquetry/chequered_parquetry_normal.jpg"
      ]
    }
    occlusionMap ImageTexture {
      url [
        "textures/parquetry/chequered_parquetry_occlusion.jpg"
      ]
    }
  }
}
E-puck {
  translation -0.907281 -0.000131708 -0.11192
  rotation -0.0003035969118685573 0.9999997097091119 0.0006988637971261488 -2.914135307179586
  controller "line_follow"
  groundSensorsSlot [
    DistanceSensor {
      translation 0 -0.02 0
      rotation 1 0 0 0.785398
      name "ir0"
      type "infra-red"
    }
    DistanceSensor {
      translation 0 -0.0175 0
      name "ir1"
      type "infra-red"
    }
    DistanceSensor {
      translation 0 -0.0125 0
      name "ir2"
      type "infra-red"
    }
    DistanceSensor {
      translation 0 -0.005 0
      name "ir3"
      type "infra-red"
    }
    DistanceSensor {
      translation 0 0.005 0
      name "ir4"
      type "infra-red"
    }
    DistanceSensor {
      translation 0 0.0125 0
      name "ir5"
      type "infra-red"
    }
    DistanceSensor {
      translation 0 0.0175 0
      name "ir6"
      type "infra-red"
    }
    DistanceSensor {
      translation 0 0.02 0
      name "ir7"
      type "infra-red"
    }
  ]
}
TrackOne {
  translation 0 -0.00753 0.31
}
Robot {
  translation 0.0135459 0.0297817 -0.57563
  rotation -0.6545868408083606 4.0622690120802564e-05 -0.7559868161484876 -3.1402253071795863
  children [
    DEF ir_panel Solid {
      translation 3.67321e-08 0.01 -0.028
      rotation 0 0 1 1.5708
      children [
        DistanceSensor {
          translation 0 0.02 0
          name "ir7"
          type "infra-red"
        }
        DistanceSensor {
          translation 0 0.0175 0
          name "ir6"
          type "infra-red"
        }
        DistanceSensor {
          translation 0 0.0125 0
          name "ir5"
          type "infra-red"
        }
        DistanceSensor {
          translation 0 0.005 0
          name "ir4"
          type "infra-red"
        }
        DistanceSensor {
          translation 0 -0.005 0
          name "ir3"
          type "infra-red"
        }
        DistanceSensor {
          translation 0 -0.0125 0
          name "ir2"
          type "infra-red"
        }
        DistanceSensor {
          translation 0 -0.02 0
          name "ir0"
          type "infra-red"
        }
        DistanceSensor {
          translation 0 -0.0175 0
          name "ir1"
          type "infra-red"
        }
        DEF panel Shape {
          appearance PBRAppearance {
            metalness 0
          }
          geometry Box {
            size 0.003 0.04 0.01
          }
        }
      ]
      name "ir_panel"
      boundingObject USE panel
      physics Physics {
      }
    }
    DEF jack Solid {
      translation 0 0 0.02
      rotation 0 1 0 0.261799
      scale 0.1 0.1 0.1
      children [
        DEF cap Shape {
          appearance PBRAppearance {
            metalness 0
          }
          geometry Capsule {
            height 0.4
            radius 0.05
          }
        }
      ]
      name "solid(2)"
      boundingObject USE cap
      physics Physics {
      }
    }
    DistanceSensor {
      translation -0.011 0 -0.019
      rotation 0 1 0 1.8325996938995748
      children [
        DEF sensor Shape {
          appearance PBRAppearance {
            metalness 0
          }
          geometry Capsule {
            height 0.05
            radius 0.005
            subdivision 26
          }
        }
      ]
      name "ds_left"
      boundingObject USE sensor
      physics Physics {
      }
    }
    DistanceSensor {
      translation 0.011 0 -0.019
      rotation 0 1 0 1.3326
      children [
        DEF sensor Shape {
          appearance PBRAppearance {
            metalness 0
          }
          geometry Capsule {
            height 0.05
            radius 0.005
            subdivision 26
          }
        }
      ]
      name "ds_right"
      boundingObject USE sensor
      physics Physics {
      }
    }
    DEF body Shape {
      appearance PBRAppearance {
      }
      geometry Sphere {
        radius 0.022
        subdivision 4
      }
    }
    HingeJoint {
      jointParameters HingeJointParameters {
        position 15.166222069349242
        anchor 0.025 0 0
      }
      device [
        RotationalMotor {
          name "left wheel motor"
        }
      ]
      endPoint Solid {
        translation 0.025 0 0
        rotation 0.6938553083454525 -0.6938578570229931 0.19268130508250406 2.7608969155561756
        children [
          DEF wheel Shape {
            appearance PBRAppearance {
            }
            geometry Cylinder {
              height 0.005
              radius 0.03
            }
          }
        ]
        boundingObject USE wheel
        physics DEF physics_wh Physics {
        }
      }
    }
    HingeJoint {
      jointParameters HingeJointParameters {
        position 18.95300027087469
        anchor -0.025 0 0
      }
      device [
        RotationalMotor {
          name "right wheel motor"
        }
      ]
      endPoint Solid {
        translation -0.025 0 0
        rotation -0.051629975086183055 0.05163016473402069 -0.9973307734960042 4.709712515134067
        children [
          USE wheel
        ]
        name "solid(1)"
        boundingObject USE wheel
        physics USE physics_wh
      }
    }
  ]
  boundingObject USE body
  physics Physics {
  }
  controller "line_follow"
}
DEF path Solid {
  translation -0.093 0 -0.58
  children [
    DEF road Shape {
      appearance PBRAppearance {
        baseColor 0 0 0
        roughness 1
        metalness 0
      }
      geometry Box {
        size 0.9 0.001 0.015
      }
    }
  ]
  name "path"
  boundingObject USE road
}
Solid {
  translation -0.535 0 -0.129999
  rotation 0 1 0 -1.5707953071795862
  children [
    USE road
  ]
}
