#VRML_SIM R2021a utf8
WorldInfo {
  coordinateSystem "NUE"
}
Viewpoint {
  orientation 0.6760871661109092 0.6980084829968188 0.23598792656532172 5.355786215550604
  position -1.3625489749166793 1.6991522112100905 1.4198970838713842
}
TexturedBackground {
}
TexturedBackgroundLight {
}
RectangleArena {
  floorSize 5 5
  floorAppearance PBRAppearance {
    baseColor 0 0 0
    roughness 1
    roughnessMap ImageTexture {
      url [
        "textures/parquetry/chequered_parquetry_occlusion.jpg"
      ]
    }
    metalness 0
    normalMap ImageTexture {
      url [
        "textures/parquetry/chequered_parquetry_normal.jpg"
      ]
    }
    occlusionMap ImageTexture {
      url [
        "textures/parquetry/chequered_parquetry_occlusion.jpg"
      ]
    }
  }
}
DEF path Solid {
  translation 0.527 0 0.3
  children [
    DEF road Shape {
      appearance PBRAppearance {
        roughness 1
        metalness 0
      }
      geometry Box {
        size 0.9 0.0001 0.03
      }
    }
  ]
  name "path(4)"
  boundingObject USE road
}
DEF path1 Solid {
  translation -0.017 0 -0.129999
  rotation 0 1 0 -1.5707953071795862
  children [
    DEF road Shape {
      appearance PBRAppearance {
        roughness 1
        metalness 0
      }
      geometry Box {
        size 0.9 0.0001 0.03
      }
    }
  ]
  name "solid(3)"
}
Robot {
  translation -0.532342 0.0400178 0.155064
  rotation -0.006826409069353844 0.0012931398237059056 -0.9999758636730258 -3.141575307179586
  children [
    DEF body Shape {
      appearance PBRAppearance {
      }
      geometry Box {
        size 0.1 0.003 0.1
      }
    }
    DEF ir_panel Solid {
      translation -3.67321e-08 0.01 -0.075
      rotation 0 0 1 1.5708
      scale 1.5 1.5 1.5
      children [
        DistanceSensor {
          translation 0 -0.0275 0
          name "ir0"
          type "infra-red"
        }
        DistanceSensor {
          translation 0 -0.025 0
          name "ir1"
          type "infra-red"
        }
        DistanceSensor {
          translation 0 -0.02 0
          name "ir2"
          type "infra-red"
        }
        DistanceSensor {
          translation 0 -0.01 0
          name "ir3"
          type "infra-red"
        }
        DistanceSensor {
          translation 0 0.01 0
          name "ir4"
          type "infra-red"
        }
        DistanceSensor {
          translation 0 0.02 0
          name "ir5"
          type "infra-red"
        }
        DistanceSensor {
          translation 0 0.025 0
          name "ir6"
          type "infra-red"
        }
        DistanceSensor {
          translation 0 0.0275 0
          name "ir7"
          type "infra-red"
        }
        DEF ir_panel Shape {
          appearance PBRAppearance {
          }
          geometry Box {
            size 0.003 0.06 0.01
          }
        }
      ]
      name "ir_panel"
      boundingObject USE ir_panel
      physics Physics {
      }
    }
    DEF ts_panel Solid {
      translation 0 0.01 -0.095
      rotation 0 0 1 1.5708
      scale 2 2 2
      children [
        DistanceSensor {
          translation 0 -0.03 0
          name "ts0"
          type "infra-red"
        }
        DistanceSensor {
          translation 0 0.03 0
          name "ts1"
          type "infra-red"
        }
        USE ir_panel
      ]
      name "ts_pane;"
    }
    DEF front_left HingeJoint {
      jointParameters HingeJointParameters {
        position 5.637151010535637
        anchor 0.075 0 -0.15
      }
      device [
        RotationalMotor {
          name "front_left"
        }
        Brake {
          name "front_left_brake"
        }
      ]
      endPoint Solid {
        translation 0.075 0 -0.15
        rotation 0.302551304184483 -0.3025524155195175 -0.903838892834101 4.611452985230338
        children [
          DEF front_wheel Shape {
            appearance PBRAppearance {
            }
            geometry Cylinder {
              height 0.005
              radius 0.04
            }
          }
        ]
        name "front_left_wheel"
        boundingObject USE front_wheel
        physics Physics {
        }
      }
    }
    DEF front_right HingeJoint {
      jointParameters HingeJointParameters {
        position 5.965399102771373
        anchor -0.075 0 -0.15
      }
      device [
        Brake {
          name "front_right_brake"
        }
        RotationalMotor {
          name "front_right"
        }
      ]
      endPoint Solid {
        translation -0.075 0 -0.15
        rotation 0.15628061254455908 -0.1562811865963576 -0.975270506505109 4.687347520839201
        children [
          USE front_wheel
        ]
        name "front_right_wheel"
        boundingObject USE front_wheel
        physics Physics {
        }
      }
    }
    DEF axel_rear Solid {
      rotation 0 0 1 1.5708
      children [
        DEF axel Shape {
          appearance PBRAppearance {
          }
          geometry Cylinder {
            height 0.145
            radius 0.002
          }
        }
      ]
      name "axel"
      boundingObject USE axel
      physics Physics {
      }
    }
    DEF axel_front Solid {
      translation 0 0 -0.15
      rotation 0 0 1 1.5708
      children [
        DEF axel Shape {
          appearance PBRAppearance {
          }
          geometry Cylinder {
            height 0.145
            radius 0.002
          }
        }
      ]
      name "axel(1)"
      boundingObject USE axel
      physics Physics {
      }
    }
    LED {
      translation 0 -0.02 0
      rotation 1 0 0 3.14159
      children [
        Shape {
          appearance PBRAppearance {
            metalness 0
            emissiveIntensity 20
          }
          geometry Sphere {
            radius 0.005
            subdivision 3
          }
        }
      ]
    }
    DEF leftwheel HingeJoint {
      jointParameters HingeJointParameters {
        position 167.19061165518875
        anchor 0.075 0 0
      }
      device [
        PositionSensor {
          name "pos_left"
        }
        RotationalMotor {
          name "left wheel motor"
        }
        Brake {
          name "brake_left"
        }
      ]
      endPoint Solid {
        translation 0.0750045 0 0
        rotation 0.693637884000445 -0.6931447137615622 -0.1960022746393206 3.53155848047172
        children [
          DEF wheel Shape {
            appearance PBRAppearance {
              baseColor 1 0.980392 0.403922
              roughness 1
              metalness 0
            }
            geometry Cylinder {
              height 0.005
              radius 0.04
            }
          }
        ]
        name "left_wheel"
        boundingObject USE wheel
        physics DEF physics_wh Physics {
        }
      }
    }
    DEF rightwheel HingeJoint {
      jointParameters HingeJointParameters {
        position 173.77985016253544
        anchor -0.075 0 0
      }
      device [
        PositionSensor {
          name "pos_right"
        }
        Brake {
          name "brake_right"
        }
        RotationalMotor {
          name "right wheel motor"
        }
      ]
      endPoint Solid {
        translation -0.07500442134343432 -4.417691654060463e-06 1.0235807421180205e-06
        rotation 0.6795960782202973 -0.6723065669083791 -0.29351839901352145 3.7120652874126625
        children [
          USE wheel
        ]
        name "right_wheel"
        boundingObject USE wheel
        physics USE physics_wh
      }
    }
  ]
  boundingObject USE body
  physics Physics {
  }
  controller "line_follow"
}
DEF path Solid {
  translation -0.093 0 -0.58
  children [
    DEF road Shape {
      appearance PBRAppearance {
        roughness 1
        metalness 0
      }
      geometry Box {
        size 0.9 0.0001 0.03
      }
    }
  ]
  name "path"
  boundingObject USE road
}
DEF path Solid {
  translation -0.093 0 -1.47
  children [
    DEF road Shape {
      appearance PBRAppearance {
        roughness 1
        metalness 0
      }
      geometry Box {
        size 0.9 0.0001 0.03
      }
    }
  ]
  name "path(1)"
  boundingObject USE road
}
DEF path Solid {
  translation 0.427 0 0.3
  children [
    DEF road Shape {
      appearance PBRAppearance {
        roughness 1
        metalness 0
      }
      geometry Box {
        size 0.9 0.0001 0.03
      }
    }
  ]
  name "path(3)"
  boundingObject USE road
}
DEF path Solid {
  translation 0.527 0 -1.47
  children [
    DEF road Shape {
      appearance PBRAppearance {
        roughness 1
        metalness 0
      }
      geometry Box {
        size 0.9 0.0001 0.03
      }
    }
  ]
  name "path(2)"
  boundingObject USE road
}
DEF path1 Solid {
  translation -0.527 0 -0.129999
  rotation 0 1 0 -1.5707953071795862
  children [
    USE road
  ]
}
DEF path1 Solid {
  translation 0.943 0 -0.129999
  rotation 0 1 0 -1.5707953071795862
  children [
    USE road
  ]
  name "solid(4)"
}
DEF path1 Solid {
  translation 0.943 0 -1.03
  rotation 0 1 0 -1.5707953071795862
  children [
    USE road
  ]
  name "solid(2)"
}
DEF path1 Solid {
  translation -0.527 0 -1.03
  rotation 0 1 0 -1.5707953071795862
  children [
    USE road
  ]
  name "solid(1)"
}
DEF ramp Transform {
  translation 0.94 0 -0.58
  rotation 0 1 0 -1.5707953071795862
  children [
    DEF rtop1 Solid {
      translation 0 0.15 0
      children [
        DEF rtop1 Shape {
          appearance PBRAppearance {
            metalness 0
          }
          geometry Box {
            size 0.35 0.0001 0.03
          }
        }
      ]
      name "rtop1"
      boundingObject USE rtop1
    }
    DEF rtop2 Solid {
      translation 0 0.15 0.088
      children [
        DEF rtop2 Shape {
          appearance PBRAppearance {
            metalness 0
          }
          geometry Box {
            size 0.03 0.0001 0.175
          }
        }
      ]
      name "rtop2"
    }
    DEF rpath1 Solid {
      translation -0.382 0.0742 0
      rotation 0 0 1 0.34906500000000046
      children [
        DEF rpath1 Shape {
          appearance PBRAppearance {
            metalness 0
          }
          geometry Box {
            size 0.438456 0.001 0.03
          }
        }
      ]
      name "rpath1"
      boundingObject USE rpath1
    }
    DEF rpath2 Solid {
      translation 0.381 0.0745 0
      rotation 0 0 1 -0.349065
      children [
        DEF rpath1 Shape {
          appearance PBRAppearance {
            metalness 0
          }
          geometry Box {
            size 0.438456 0.001 0.03
          }
        }
      ]
      name "rpath2"
      boundingObject USE rpath1
    }
    DEF rpath3 Transform {
      translation 0 0.0745 0.381
      rotation 1 0 0 0.349065
      children [
        Solid {
          rotation 0 1 0 1.5708
          children [
            USE rpath1
          ]
          name "rpath3"
          boundingObject USE rpath1
        }
      ]
    }
    DEF rampo Solid {
      translation -0.587 0 -0.175
      scale 0.001 0.001 0.001
      children [
        DEF SHAPE Shape {
          appearance PBRAppearance {
            baseColor 0 0 0
            roughness 1
            metalness 0
            name "DefaultMaterial"
          }
          geometry IndexedFaceSet {
            coord Coordinate {
              point [
                412 150 350, 412 5.55112e-14 350, 412 0 762, 762 5.55112e-14 350, 762 150 350, 762 0 762, 762 150 350, 412 150 350, 412 0 762, 762 0 762, 412 150 0, 762 150 0, 0 5.55112e-14 0, 1174 5.55112e-14 0, 412 5.55112e-14 350, 0 5.55112e-14 350, 0 5.55112e-14 0, 1174 5.55112e-14 0, 0 5.55112e-14 350, 412 150 350, 0 5.55112e-14 0, 412 150 0, 1174 5.55112e-14 350, 762 5.55112e-14 350, 762 150 0, 1174 5.55112e-14 350, 1174 5.55112e-14 0, 412 5.55112e-14 350, 412 150 350, 0 5.55112e-14 350, 412 0 762, 762 0 762, 1174 5.55112e-14 350, 762 150 350, 762 5.55112e-14 350, 762 150 350, 412 150 350, 762 150 0, 412 150 0, 762 150 350
              ]
            }
            normal Normal {
              vector [
                -1 0 0, -1 0 0, -1 0 0, 1 0 0, 1 0 0, 1 0 0, 0 0.93966 0.342109, 0 0.93966 0.342109, 0 0.93966 0.342109, 0 0.93966 0.342109, 0 0 -1, 0 0 -1, 0 0 -1, 0 0 -1, 0 -1 0, 0 -1 0, 0 -1 0, 0 -1 0, -0.342109 0.93966 0, -0.342109 0.93966 0, -0.342109 0.93966 0, -0.342109 0.93966 0, 0 -1 0, 0 -1 0, 0.342109 0.93966 0, 0.342109 0.93966 0, 0.342109 0.93966 0, 0 0 1, 0 0 1, 0 0 1, 0 -1 -1.34736e-16, 0 -1 -1.34736e-16, 0 0 1, 0 0 1, 0 0 1, 0.342109 0.93966 0, 0 1 0, 0 1 0, 0 1 0, 0 1 0
              ]
            }
            coordIndex [
              0, 1, 2, -1, 3, 4, 5, -1, 6, 7, 8, -1, 9, 6, 8, -1, 10, 11, 12, -1, 11, 13, 12, -1, 14, 15, 16, -1, 17, 14, 16, -1, 18, 19, 20, -1, 19, 21, 20, -1, 22, 23, 17, -1, 23, 14, 17, -1, 24, 25, 26, -1, 27, 28, 29, -1, 23, 30, 14, -1, 31, 30, 23, -1, 32, 33, 34, -1, 24, 35, 25, -1, 36, 37, 38, -1, 36, 39, 37, -1
            ]
          }
        }
      ]
      name ""
      boundingObject USE SHAPE
    }
  ]
}
